Workbook

Sheet requirements
A1: altair | C1: 5.2.0 | D1: =IF(ISBLANK(C1),B1,C1) -> 5.2.0
A2: asttokens | B2: file:///home/conda/feedstock_root/build_artifacts/asttokens_1698341106958/work | D2: =IF(ISBLANK(C2),B2,C2) -> file:///home/conda/feedstock_root/build_artifacts/asttokens_1698341106958/work
A3: attrs | C3: 23.1.0 | D3: =IF(ISBLANK(C3),B3,C3) -> 23.1.0
A4: blinker | C4: 1.7.0 | D4: =IF(ISBLANK(C4),B4,C4) -> 1.7.0
A5: cachetools | C5: 5.3.2 | D5: =IF(ISBLANK(C5),B5,C5) -> 5.3.2
A6: certifi | C6: 2023.11.17 | D6: =IF(ISBLANK(C6),B6,C6) -> 2023.11.17
A7: charset-normalizer | C7: 3.3.2 | D7: =IF(ISBLANK(C7),B7,C7) -> 3.3.2
A8: click | C8: 8.1.7 | D8: =IF(ISBLANK(C8),B8,C8) -> 8.1.7
A9: colorama | B9: file:///home/conda/feedstock_root/build_artifacts/colorama_1666700638685/work | D9: =IF(ISBLANK(C9),B9,C9) -> file:///home/conda/feedstock_root/build_artifacts/colorama_1666700638685/work
A10: comm | B10: file:///home/conda/feedstock_root/build_artifacts/comm_1691044910542/work | D10: =IF(ISBLANK(C10),B10,C10) -> file:///home/conda/feedstock_root/build_artifacts/comm_1691044910542/work
A11: contourpy | C11: 1.2.0 | D11: =IF(ISBLANK(C11),B11,C11) -> 1.2.0
A12: cycler | C12: 0.12.1 | D12: =IF(ISBLANK(C12),B12,C12) -> 0.12.1
A13: debugpy | B13: file:///C:/b/abs_c0y1fjipt2/croot/debugpy_1690906864587/work | D13: =IF(ISBLANK(C13),B13,C13) -> file:///C:/b/abs_c0y1fjipt2/croot/debugpy_1690906864587/work
A14: decorator | B14: file:///home/conda/feedstock_root/build_artifacts/decorator_1641555617451/work | D14: =IF(ISBLANK(C14),B14,C14) -> file:///home/conda/feedstock_root/build_artifacts/decorator_1641555617451/work
A15: exceptiongroup | B15: file:///home/conda/feedstock_root/build_artifacts/exceptiongroup_1700579780973/work | D15: =IF(ISBLANK(C15),B15,C15) -> file:///home/conda/feedstock_root/build_artifacts/exceptiongroup_1700579780973/work
A16: executing | B16: file:///home/conda/feedstock_root/build_artifacts/executing_1698579936712/work | D16: =IF(ISBLANK(C16),B16,C16) -> file:///home/conda/feedstock_root/build_artifacts/executing_1698579936712/work
A17: feature-engine | C17: 1.6.2 | D17: =IF(ISBLANK(C17),B17,C17) -> 1.6.2
A18: fonttools | C18: 4.46.0 | D18: =IF(ISBLANK(C18),B18,C18) -> 4.46.0
A19: gitdb | C19: 4.0.11 | D19: =IF(ISBLANK(C19),B19,C19) -> 4.0.11
A20: GitPython | C20: 3.1.40 | D20: =IF(ISBLANK(C20),B20,C20) -> 3.1.40
A21: idna | C21: 3.6 | D21: =IF(ISBLANK(C21),B21,C21) -> 3.6
A22: importlib-metadata | C22: 6.11.0 | D22: =IF(ISBLANK(C22),B22,C22) -> 6.11.0
A23: ipykernel | B23: file:///D:/bld/ipykernel_1698244157926/work | D23: =IF(ISBLANK(C23),B23,C23) -> file:///D:/bld/ipykernel_1698244157926/work
A24: ipython | B24: file:///D:/bld/ipython_1701831845989/work | D24: =IF(ISBLANK(C24),B24,C24) -> file:///D:/bld/ipython_1701831845989/work
A25: jedi | B25: file:///home/conda/feedstock_root/build_artifacts/jedi_1696326070614/work | D25: =IF(ISBLANK(C25),B25,C25) -> file:///home/conda/feedstock_root/build_artifacts/jedi_1696326070614/work
A26: Jinja2 | C26: 3.1.2 | D26: =IF(ISBLANK(C26),B26,C26) -> 3.1.2
A27: joblib | C27: 1.3.2 | D27: =IF(ISBLANK(C27),B27,C27) -> 1.3.2
A28: jsonschema | C28: 4.20.0 | D28: =IF(ISBLANK(C28),B28,C28) -> 4.20.0
A29: jsonschema-specifications | C29: 2023.11.2 | D29: =IF(ISBLANK(C29),B29,C29) -> 2023.11.2
A30: jupyter_client | B30: file:///home/conda/feedstock_root/build_artifacts/jupyter_client_1699283905679/work | D30: =IF(ISBLANK(C30),B30,C30) -> file:///home/conda/feedstock_root/build_artifacts/jupyter_client_1699283905679/work
A31: jupyter_core | B31: file:///D:/bld/jupyter_core_1698673822668/work | D31: =IF(ISBLANK(C31),B31,C31) -> file:///D:/bld/jupyter_core_1698673822668/work
A32: kiwisolver | C32: 1.4.5 | D32: =IF(ISBLANK(C32),B32,C32) -> 1.4.5
A33: markdown-it-py | C33: 3.0.0 | D33: =IF(ISBLANK(C33),B33,C33) -> 3.0.0
A34: MarkupSafe | C34: 2.1.3 | D34: =IF(ISBLANK(C34),B34,C34) -> 2.1.3
A35: matplotlib | C35: 3.8.2 | D35: =IF(ISBLANK(C35),B35,C35) -> 3.8.2
A36: matplotlib-inline | B36: file:///home/conda/feedstock_root/build_artifacts/matplotlib-inline_1660814786464/work | D36: =IF(ISBLANK(C36),B36,C36) -> file:///home/conda/feedstock_root/build_artifacts/matplotlib-inline_1660814786464/work
A37: mdurl | C37: 0.1.2 | D37: =IF(ISBLANK(C37),B37,C37) -> 0.1.2
A38: nest-asyncio | B38: file:///home/conda/feedstock_root/build_artifacts/nest-asyncio_1697083700168/work | D38: =IF(ISBLANK(C38),B38,C38) -> file:///home/conda/feedstock_root/build_artifacts/nest-asyncio_1697083700168/work
A39: numpy | C39: 1.26.2 | D39: =IF(ISBLANK(C39),B39,C39) -> 1.26.2
A40: packaging | B40: file:///home/conda/feedstock_root/build_artifacts/packaging_1696202382185/work | D40: =IF(ISBLANK(C40),B40,C40) -> file:///home/conda/feedstock_root/build_artifacts/packaging_1696202382185/work
...

Sheet matching
A1: altair | B1: 5.2.0 | C1: pypi_0 | D1: pypi | E1: =VLOOKUP(A1,requirements!$A$1:$D$85,4,0) -> 5.2.0
A2: asttokens | B2: 2.4.1 | C2: pyhd8ed1ab_0 | D2: conda-forge | E2: =VLOOKUP(A2,requirements!$A$1:$D$85,4,0) -> file:///home/conda/feedstock_root/build_artifacts/asttokens_1698341106958/work
A3: attrs | B3: 23.1.0 | C3: pypi_0 | D3: pypi | E3: =VLOOKUP(A3,requirements!$A$1:$D$85,4,0) -> 23.1.0
A4: blinker | B4: 1.7.0 | C4: pypi_0 | D4: pypi | E4: =VLOOKUP(A4,requirements!$A$1:$D$85,4,0) -> 1.7.0
A5: bzip2 | B5: 1.0.8 | C5: he774522_0 | E5: =VLOOKUP(A5,requirements!$A$1:$D$85,4,0) -> #N/A
A6: ca-certificates | B6: 2023.11.17 | C6: h56e8100_0 | D6: conda-forge | E6: =VLOOKUP(A6,requirements!$A$1:$D$85,4,0) -> #N/A
A7: cachetools | B7: 5.3.2 | C7: pypi_0 | D7: pypi | E7: =VLOOKUP(A7,requirements!$A$1:$D$85,4,0) -> 5.3.2
A8: certifi | B8: 2023.11.17 | C8: pypi_0 | D8: pypi | E8: =VLOOKUP(A8,requirements!$A$1:$D$85,4,0) -> 2023.11.17
A9: charset-normalizer | B9: 3.3.2 | C9: pypi_0 | D9: pypi | E9: =VLOOKUP(A9,requirements!$A$1:$D$85,4,0) -> 3.3.2
A10: click | B10: 8.1.7 | C10: pypi_0 | D10: pypi | E10: =VLOOKUP(A10,requirements!$A$1:$D$85,4,0) -> 8.1.7
A11: colorama | B11: 0.4.6 | C11: pyhd8ed1ab_0 | D11: conda-forge | E11: =VLOOKUP(A11,requirements!$A$1:$D$85,4,0) -> file:///home/conda/feedstock_root/build_artifacts/colorama_1666700638685/work
A12: comm | B12: 0.1.4 | C12: pyhd8ed1ab_0 | D12: conda-forge | E12: =VLOOKUP(A12,requirements!$A$1:$D$85,4,0) -> file:///home/conda/feedstock_root/build_artifacts/comm_1691044910542/work
A13: contourpy | B13: 1.2.0 | C13: pypi_0 | D13: pypi | E13: =VLOOKUP(A13,requirements!$A$1:$D$85,4,0) -> 1.2.0
A14: cycler | B14: 0.12.1 | C14: pypi_0 | D14: pypi | E14: =VLOOKUP(A14,requirements!$A$1:$D$85,4,0) -> 0.12.1
A15: debugpy | B15: 1.6.7 | C15: py311hd77b12b_0 | E15: =VLOOKUP(A15,requirements!$A$1:$D$85,4,0) -> file:///C:/b/abs_c0y1fjipt2/croot/debugpy_1690906864587/work
A16: decorator | B16: 5.1.1 | C16: pyhd8ed1ab_0 | D16: conda-forge | E16: =VLOOKUP(A16,requirements!$A$1:$D$85,4,0) -> file:///home/conda/feedstock_root/build_artifacts/decorator_1641555617451/work
A17: exceptiongroup | B17: 1.2.0 | C17: pyhd8ed1ab_0 | D17: conda-forge | E17: =VLOOKUP(A17,requirements!$A$1:$D$85,4,0) -> file:///home/conda/feedstock_root/build_artifacts/exceptiongroup_1700579780973/work
A18: executing | B18: 2.0.1 | C18: pyhd8ed1ab_0 | D18: conda-forge | E18: =VLOOKUP(A18,requirements!$A$1:$D$85,4,0) -> file:///home/conda/feedstock_root/build_artifacts/executing_1698579936712/work
A19: feature-engine | B19: 1.6.2 | C19: pypi_0 | D19: pypi | E19: =VLOOKUP(A19,requirements!$A$1:$D$85,4,0) -> 1.6.2
A20: fonttools | B20: 4.46.0 | C20: pypi_0 | D20: pypi | E20: =VLOOKUP(A20,requirements!$A$1:$D$85,4,0) -> 4.46.0
A21: gitdb | B21: 4.0.11 | C21: pypi_0 | D21: pypi | E21: =VLOOKUP(A21,requirements!$A$1:$D$85,4,0) -> 4.0.11
A22: gitpython | B22: 3.1.40 | C22: pypi_0 | D22: pypi | E22: =VLOOKUP(A22,requirements!$A$1:$D$85,4,0) -> 3.1.40
A23: idna | B23: 3.6 | C23: pypi_0 | D23: pypi | E23: =VLOOKUP(A23,requirements!$A$1:$D$85,4,0) -> 3.6
A24: importlib-metadata | B24: 6.11.0 | C24: pypi_0 | D24: pypi | E24: =VLOOKUP(A24,requirements!$A$1:$D$85,4,0) -> 6.11.0
A25: importlib_metadata | B25: 7.0.0 | C25: hd8ed1ab_0 | D25: conda-forge | E25: =VLOOKUP(A25,requirements!$A$1:$D$85,4,0) -> #N/A
A26: ipykernel | B26: 6.26.0 | C26: pyha63f2e9_0 | D26: conda-forge | E26: =VLOOKUP(A26,requirements!$A$1:$D$85,4,0) -> file:///D:/bld/ipykernel_1698244157926/work
A27: ipython | B27: 8.18.1 | C27: pyh7428d3b_3 | D27: conda-forge | E27: =VLOOKUP(A27,requirements!$A$1:$D$85,4,0) -> file:///D:/bld/ipython_1701831845989/work
A28: jedi | B28: 0.19.1 | C28: pyhd8ed1ab_0 | D28: conda-forge | E28: =VLOOKUP(A28,requirements!$A$1:$D$85,4,0) -> file:///home/conda/feedstock_root/build_artifacts/jedi_1696326070614/work
A29: jinja2 | B29: 3.1.2 | C29: pypi_0 | D29: pypi | E29: =VLOOKUP(A29,requirements!$A$1:$D$85,4,0) -> 3.1.2
A30: joblib | B30: 1.3.2 | C30: pypi_0 | D30: pypi | E30: =VLOOKUP(A30,requirements!$A$1:$D$85,4,0) -> 1.3.2
A31: jsonschema | B31: 4.20.0 | C31: pypi_0 | D31: pypi | E31: =VLOOKUP(A31,requirements!$A$1:$D$85,4,0) -> 4.20.0
A32: jsonschema-specifications | B32: 2023.11.2 | C32: pypi_0 | D32: pypi | E32: =VLOOKUP(A32,requirements!$A$1:$D$85,4,0) -> 2023.11.2
A33: jupyter_client | B33: 8.6.0 | C33: pyhd8ed1ab_0 | D33: conda-forge | E33: =VLOOKUP(A33,requirements!$A$1:$D$85,4,0) -> file:///home/conda/feedstock_root/build_artifacts/jupyter_client_1699283905679/work
A34: jupyter_core | B34: 5.5.0 | C34: py311h1ea47a8_0 | D34: conda-forge | E34: =VLOOKUP(A34,requirements!$A$1:$D$85,4,0) -> file:///D:/bld/jupyter_core_1698673822668/work
A35: kiwisolver | B35: 1.4.5 | C35: pypi_0 | D35: pypi | E35: =VLOOKUP(A35,requirements!$A$1:$D$85,4,0) -> 1.4.5
A36: libffi | B36: 3.4.4 | C36: hd77b12b_0 | E36: =VLOOKUP(A36,requirements!$A$1:$D$85,4,0) -> #N/A
A37: libsodium | B37: 1.0.18 | C37: h8d14728_1 | D37: conda-forge | E37: =VLOOKUP(A37,requirements!$A$1:$D$85,4,0) -> #N/A
A38: markdown-it-py | B38: 3.0.0 | C38: pypi_0 | D38: pypi | E38: =VLOOKUP(A38,requirements!$A$1:$D$85,4,0) -> 3.0.0
A39: markupsafe | B39: 2.1.3 | C39: pypi_0 | D39: pypi | E39: =VLOOKUP(A39,requirements!$A$1:$D$85,4,0) -> 2.1.3
A40: matplotlib | B40: 3.8.2 | C40: pypi_0 | D40: pypi | E40: =VLOOKUP(A40,requirements!$A$1:$D$85,4,0) -> 3.8.2
...

Sheet Sheet3
